try {
    throw new Error
} catch {
    console.log("catchの処理")
}
